2019-07-18T13:56:57|CRITICAL|root|Unhandled exception:Traceback (most recent call last):
  File "C:\Users\MurthyLab\Anaconda3\lib\site-packages\ScopeFoundry\hardware.py", line 208, in enable_connection
    raise err
  File "C:\Users\MurthyLab\Anaconda3\lib\site-packages\ScopeFoundry\hardware.py", line 204, in enable_connection
    self.connect()
  File "C:\Users\MurthyLab\Desktop\AntCam-master\AntCamHW\flircam\camera_hw.py", line 22, in connect
    self.dev = CameraDev(self.settings.camera_id.value())
TypeError: 'int' object is not callable

