2019-07-17T21:31:53|CRITICAL|root|Unhandled exception:Traceback (most recent call last):
  File "C:/Users/MurthyLab/Desktop/AntCam-master/main_interface.py", line 61, in <module>
    app = AntCamApp(sys.argv)
  File "C:\Users\MurthyLab\Anaconda3\lib\site-packages\ScopeFoundry\base_app.py", line 332, in __init__
    self.setup()
  File "C:/Users/MurthyLab/Desktop/AntCam-master/main_interface.py", line 46, in setup
    self.add_measurement(SelinaTraining(self))
  File "C:\Users\MurthyLab\Anaconda3\lib\site-packages\ScopeFoundry\measurement.py", line 93, in __init__
    self.setup()
  File "C:\Users\MurthyLab\Desktop\AntCam-master\AntCamMS\Selina_Contingency.py", line 96, in setup
    self.wide_cam = self.app.hardware['wide_cam']
  File "C:\Users\MurthyLab\Anaconda3\lib\site-packages\ScopeFoundry\helper_funcs.py", line 31, in __getitem__
    return self._odict[key]
KeyError: 'wide_cam'

